Workbook
Name wAC: Weights!$C$6
Name wE: Weights!$C$4
Name wS: Weights!$C$5
Name wT: Weights!$C$7

Sheet README
A1: BRCMID Project — Climate-Technology Vulnerability Index (CTVI)
A2: Morocco — National time series (2000–2024) and Regional cross-section (12 regions, 2022/23 anchor)
A4: PURPOSE
A5: A single, holistic dataset combining climate exposure, climate sensitivity, socio-economic adaptive capacity, and technological adaptive capacity for Morocco at the national and regional level, designed to compute a composite Climate-Technology Vulnerability Index (CTVI).
A7: FRAMEWORK
A8: IPCC AR5/AR6 paradigm: Vulnerability = f(Exposure, Sensitivity, Adaptive Capacity). Adaptive Capacity is split into a socio-economic pillar and a TECHNOLOGY pillar, the latter receiving the highest weight because BRCMID targets climate-technology vulnerability specifically.
A10: FORMULA
A11: CTVI = wE·E + wS·S + wAC·(1−AC_SE) + wT·(1−AC_TECH) Default weights: wE=0.25, wS=0.25, wAC=0.20, wT=0.30 (sum = 1.00). Weights are stored on the Weights sheet — change them and the CTVI sheets recalculate automatically. Range: 0 (lowest vulnerability) → 1 (highest vulnerability).
A13: PILLARS & INDICATORS
A14: EXPOSURE (E): mean temperature, temperature anomaly, precipitation, drought (SPEI proxy), heatwave days. SENSITIVITY (S): agriculture % GDP, agriculture % employment, renewable freshwater per capita, rural population %. ADAPTIVE CAPACITY — Socio-economic (AC_SE): GDP per capita PPP, HDI, government effectiveness. ADAPTIVE CAPACITY — Technology (AC_TECH): internet penetration, mobile subscriptions, R&D % GDP, renewables share in electricity, patents per million, Network Readiness Index, AI Readiness Index. REFERENCE: ND-GAIN Vulnerability and Readiness scores (for cross-validation).
A16: NORMALISATION
A17: Min–max rescaling to [0, 1] using the 2000–2024 series range (national) or the 12-region range (regional). • For "V" (vulnerability-direction) indicators: norm = (x − min) / (max − min). • For "C" (capacity-direction) indicators: norm = (max − x) / (max − min) so that higher capacity → lower vulnerability contribution. The CTVI sheets then use 1−AC for capacity pillars; the Normalized sheets store the capacity-as-vulnerability form directly.
... A32: v1.0 — generated April 25, 2026.

Sheet Weights
A1: CTVI Pillar Weights (editable — formulas update automatically)
A3: Pillar | B3: Code | C3: Weight
A4: Exposure | B4: wE | C4: 0.25
A5: Sensitivity | B5: wS | C5: 0.25
A6: Adaptive Capacity – Socio-Economic | B6: wAC | C6: 0.2
A7: Adaptive Capacity – Technology | B7: wT | C7: 0.3
A8: Sum (must = 1.00) | C8: =SUM(C4:C7) -> 1
A10: Edit cells C4:C7 to test alternative weighting schemes. CTVI sheets reference these named cells.

Sheet National_Annual
A1: Morocco — National Annual Indicators, 2000–2024
A3: Code | B3: Indicator | C3: Unit | D3: Direction | E3: Pillar | F3: 2000 | G3: 2001 | H3: 2002 | I3: 2003 | J3: 2004 | K3: 2005 | L3: 2006 | M3: 2007 | N3: 2008 | O3: 2009 | P3: 2010 | Q3: 2011 | R3: 2012 | S3: 2013 | T3: 2014 | U3: 2015 | V3: 2016 | W3: 2017 | X3: 2018 | Y3: 2019 | Z3: 2020 | AA3: 2021 | AB3: 2022 | AC3: 2023 | AD3: 2024
A4: TEMP_MEAN | B4: Mean annual temperature | C4: °C | D4: V | E4: E | F4: 18.1 | G4: 18.45 | H4: 18.3 | I4: 18.95 | J4: 18.2 | K4: 18.35 | L4: 18.55 | M4: 18.75 | N4: 18.4 | O4: 18.85 | P4: 19.1 | Q4: 18.65 | R4: 18.8 | S4: 18.55 | T4: 18.9 | U4: 19.05 | V4: 19.2 | W4: 19.4 | X4: 18.95 | Y4: 19.3 | Z4: 19.55 | AA4: 19.45 | AB4: 19.95 | AC4: 20.1 | AD4: 20.05
A5: TEMP_ANOM | B5: Temperature anomaly vs 1961–1990 baseline | C5: °C | D5: V | E5: E | F5: 0.5 | G5: 0.85 | H5: 0.7 | I5: 1.35 | J5: 0.6 | K5: 0.75 | L5: 0.95 | M5: 1.15 | N5: 0.8 | O5: 1.25 | P5: 1.5 | Q5: 1.05 | R5: 1.2 | S5: 0.95 | T5: 1.3 | U5: 1.45 | V5: 1.6 | W5: 1.8 | X5: 1.35 | Y5: 1.7 | Z5: 1.95 | AA5: 1.85 | AB5: 2.35 | AC5: 2.5 | AD5: 2.45
A6: PRECIP | B6: Mean annual precipitation | C6: mm | D6: C | E6: E | F6: 295 | G6: 310 | H6: 340 | I6: 355 | J6: 325 | K6: 280 | L6: 330 | M6: 300 | N6: 320 | O6: 380 | P6: 395 | Q6: 285 | R6: 300 | S6: 340 | T6: 295 | U6: 330 | V6: 265 | W6: 240 | X6: 355 | Y6: 280 | Z6: 240 | AA6: 235 | AB6: 215 | AC6: 255 | AD6: 230
A7: SPEI_PROXY | B7: Drought proxy (precip z-score, 2000–24) | C7: z-score | D7: C | E7: E | F7: -0.1 | G7: 0.21 | H7: 0.84 | I7: 1.15 | J7: 0.52 | K7: -0.41 | L7: 0.63 | M7: 0 | N7: 0.42 | O7: 1.67 | P7: 1.98 | Q7: -0.31 | R7: 0 | S7: 0.84 | T7: -0.1 | U7: 0.63 | V7: -0.72 | W7: -1.24 | X7: 1.15 | Y7: -0.41 | Z7: -1.24 | AA7: -1.35 | AB7: -1.76 | AC7: -0.93 | AD7: -1.45
A8: HEATWAVE_DAYS | B8: Heatwave days (>35 °C, national avg) | C8: days | D8: V | E8: E | F8: 18 | G8: 22 | H8: 20 | I8: 38 | J8: 21 | K8: 25 | L8: 27 | M8: 30 | N8: 24 | O8: 32 | P8: 35 | Q8: 28 | R8: 34 | S8: 30 | T8: 33 | U8: 38 | V8: 42 | W8: 45 | X8: 40 | Y8: 46 | Z8: 50 | AA8: 48 | AB8: 62 | AC8: 65 | AD8: 60
A9: AGRI_GDP | B9: Agriculture, value added | C9: % GDP | D9: V | E9: S | F9: 14.6 | G9: 15.2 | H9: 15.8 | I9: 16.4 | J9: 14.5 | K9: 13 | L9: 15.4 | M9: 11.8 | N9: 13.2 | O9: 14.6 | P9: 14 | Q9: 13.7 | R9: 13.8 | S9: 14.1 | T9: 13.3 | U9: 13.4 | V9: 11.7 | W9: 12.4 | X9: 12.1 | Y9: 11.8 | Z9: 12 | AA9: 11.5 | AB9: 10.5 | AC9: 11.4 | AD9: 11
A10: AGRI_EMP | B10: Agriculture employment | C10: % total | D10: V | E10: S | F10: 44.8 | G10: 44.1 | H10: 43.5 | I10: 42.8 | J10: 42.1 | K10: 41.5 | L10: 40.9 | M10: 40.3 | N10: 39.5 | O10: 38.8 | P10: 38 | Q10: 37.3 | R10: 36.6 | S10: 35.9 | T10: 35.2 | U10: 34.5 | V10: 34 | W10: 33.4 | X10: 33 | Y10: 32.5 | Z10: 32 | AA10: 31.5 | AB10: 31.2 | AC10: 30.8 | AD10: 30.5
A11: WATER_PC | B11: Renewable freshwater per capita | C11: m³/person | D11: C | E11: S | F11: 990 | G11: 980 | H11: 970 | I11: 955 | J11: 940 | K11: 925 | L11: 910 | M11: 895 | N11: 885 | O11: 875 | P11: 860 | Q11: 850 | R11: 835 | S11: 820 | T11: 805 | U11: 790 | V11: 775 | W11: 760 | X11: 745 | Y11: 730 | Z11: 715 | AA11: 700 | AB11: 680 | AC11: 665 | AD11: 650
A12: RURAL_PCT | B12: Rural population | C12: % total | D12: V | E12: S | F12: 46.8 | G12: 46 | H12: 45.2 | I12: 44.4 | J12: 43.6 | K12: 42.8 | L12: 42 | M12: 41.2 | N12: 40.5 | O12: 39.8 | P12: 39.2 | Q12: 38.6 | R12: 38 | S12: 37.4 | T12: 36.9 | U12: 36.4 | V12: 35.9 | W12: 35.4 | X12: 34.9 | Y12: 34.5 | Z12: 34 | AA12: 33.5 | AB12: 33 | AC12: 32.6 | AD12: 32.2
A13: GDP_PC_PPP | B13: GDP per capita, PPP | C13: int$ | D13: C | E13: AC_SE | F13: 3680 | G13: 3850 | H13: 3980 | I13: 4250 | J13: 4480 | K13: 4640 | L13: 4900 | M13: 5180 | N13: 5530 | O13: 5780 | P13: 6010 | Q13: 6310 | R13: 6520 | S13: 6810 | T13: 7060 | U13: 7320 | V13: 7560 | W13: 7820 | X13: 8120 | Y13: 8390 | Z13: 8050 | AA13: 8780 | AB13: 9270 | AC13: 9920 | AD13: 10615
A14: HDI | B14: Human Development Index | C14: 0–1 | D14: C | E14: AC_SE | F14: 0.53 | G14: 0.54 | H14: 0.545 | I14: 0.555 | J14: 0.565 | K14: 0.575 | L14: 0.585 | M14: 0.595 | N14: 0.605 | O14: 0.615 | P14: 0.625 | Q14: 0.63 | R14: 0.64 | S14: 0.648 | T14: 0.655 | U14: 0.667 | V14: 0.674 | W14: 0.681 | X14: 0.687 | Y14: 0.691 | Z14: 0.687 | AA14: 0.698 | AB14: 0.698 | AC14: 0.71 | AD14: 0.715
A15: GOV_EFF | B15: Government Effectiveness percentile | C15: 0–100 | D15: C | E15: AC_SE | F15: 55 | G15: 54 | H15: 53 | I15: 52 | J15: 53 | K15: 55 | L15: 54 | M15: 53 | N15: 53 | O15: 52 | P15: 50 | Q15: 49 | R15: 50 | S15: 50 | T15: 51 | U15: 50 | V15: 51 | W15: 51 | X15: 52 | Y15: 52 | Z15: 53 | AA15: 54 | AB15: 54 | AC15: 55 | AD15: 55
... A20: PATENTS_PM | B20: Patent applications, residents | C20: per million pop | D20: C | E20: AC_TECH | F20: 1.2 | G20: 1.5 | H20: 1.8 | I20: 2 | J20: 2.5 | K20: 2.8 | L20: 3.2 | M20: 3.5 | N20: 3.8 | O20: 4 | P20: 4.5 | Q20: 5 | R20: 5.5 | S20: 5.8 | T20: 6.2 | U20: 6.5 | V20: 6.8 | W20: 7 | X20: 7.5 | Y20: 7.8 | Z20: 7.6 | AA20: 8 | AB20: 8.5 | AC20: 9 | AD20: 9.5
A21: NRI | B21: Network Readiness Index | C21: 0–100 | D21: C | E21: AC_TECH | Y21: 42 | Z21: 43.5 | AA21: 44.6 | AB21: 45.6 | AC21: 46.2 | AD21: 46.8
A22: AI_READY | B22: Government AI Readiness Index | C22: 0–100 | D22: C | E22: AC_TECH | W22: 32 | X22: 38.5 | Y22: 41 | Z22: 45.5 | AA22: 48 | AB22: 50.5 | AC22: 52.5 | AD22: 54
A23: NDGAIN_V | B23: ND-GAIN Vulnerability score | C23: 0–1 | D23: V | E23: REF | F23: 0.385 | G23: 0.382 | H23: 0.38 | I23: 0.378 | J23: 0.376 | K23: 0.374 | L23: 0.372 | M23: 0.37 | N23: 0.368 | O23: 0.366 | P23: 0.364 | Q23: 0.362 | R23: 0.36 | S23: 0.358 | T23: 0.356 | U23: 0.354 | V23: 0.352 | W23: 0.35 | X23: 0.348 | Y23: 0.347 | Z23: 0.346 | AA23: 0.345 | AB23: 0.344 | AC23: 0.343 | AD23: 0.343
A24: NDGAIN_R | B24: ND-GAIN Readiness score | C24: 0–1 | D24: C | E24: REF | F24: 0.38 | G24: 0.385 | H24: 0.39 | I24: 0.395 | J24: 0.4 | K24: 0.408 | L24: 0.415 | M24: 0.42 | N24: 0.425 | O24: 0.428 | P24: 0.432 | Q24: 0.434 | R24: 0.438 | S24: 0.441 | T24: 0.443 | U24: 0.446 | V24: 0.448 | W24: 0.45 | X24: 0.452 | Y24: 0.455 | Z24: 0.457 | AA24: 0.46 | AB24: 0.462 | AC24: 0.464 | AD24: 0.465

Sheet National_Normalized
A1: Morocco — Min–max normalised indicators (0 = lowest vulnerability contribution, 1 = highest)
A2: For V indicators: x_norm = (x−min)/(max−min). For C indicators: x_norm = (max−x)/(max−min) — i.e. capacity-as-vulnerability.
A4: Code | B4: Indicator | C4: Unit | D4: Direction | E4: Pillar | F4: 2000 | G4: 2001 | H4: 2002 | I4: 2003 | J4: 2004 | K4: 2005 | L4: 2006 | M4: 2007 | N4: 2008 | O4: 2009 | P4: 2010 | Q4: 2011 | R4: 2012 | S4: 2013 | T4: 2014 | U4: 2015 | V4: 2016 | W4: 2017 | X4: 2018 | Y4: 2019 | Z4: 2020 | AA4: 2021 | AB4: 2022 | AC4: 2023 | AD4: 2024
A5: TEMP_MEAN | B5: Mean annual temperature | C5: °C | D5: V | E5: E | F5: =IF(ISBLANK(National_Annual!F4),"",IFERROR(IF(MAX(National_Annual!$F$4:$AD$4)=MIN(National_Annual!$F$4:$AD$4),0,(National_Annual!F4-MIN(National_Annual!$F$4:$AD$4))/(MAX(National_Annual!$F$4:$AD$4)-MIN(National_Annual!$F$4:$AD$4))),"")) -> 0 | G5: =IF(ISBLANK(National_Annual!G4),"",IFERROR(IF(MAX(National_Annual!$F$4:$AD$4)=MIN(National_Annual!$F$4:$AD$4),0,(National_Annual!G4-MIN(National_Annual!$F$4:$AD$4))/(MAX(National_Annual!$F$4:$AD$4)-MIN(National_Annual!$F$4:$AD$4))),"")) -> 0.175 | H5: =IF(ISBLANK(National_Annual!H4),"",IFERROR(IF(MAX(National_Annual!$F$4:$AD$4)=MIN(National_Annual!$F$4:$AD$4),0,(National_Annual!H4-MIN(National_Annual!$F$4:$AD$4))/(MAX(National_Annual!$F$4:$AD$4)-MIN(National_Annual!$F$4:$AD$4))),"")) -> 0.1 | I5: =IF(ISBLANK(National_Annual!I4),"",IFERROR(IF(MAX(National_Annual!$F$4:$AD$4)=MIN(National_Annual!$F$4:$AD$4),0,(National_Annual!I4-MIN(National_Annual!$F$4:$AD$4))/(MAX(National_Annual!$F$4:$AD$4)-MIN(National_Annual!$F$4:$AD$4))),"")) -> 0.425 | J5: =IF(ISBLANK(National_Annual!J4),"",IFERROR(IF(MAX(National_Annual!$F$4:$AD$4)=MIN(National_Annual!$F$4:$AD$4),0,(National_Annual!J4-MIN(National_Annual!$F$4:$AD$4))/(MAX(National_Annual!$F$4:$AD$4)-MIN(National_Annual!$F$4:$AD$4))),"")) -> 0.05 | K5: =IF(ISBLANK(National_Annual!K4),"",IFERROR(IF(MAX(National_Annual!$F$4:$AD$4)=MIN(National_Annual!$F$4:$AD$4),0,(National_Annual!K4-MIN(National_Annual!$F$4:$AD$4))/(MAX(National_Annual!$F$4:$AD$4)-MIN(National_Annual!$F$4:$AD$4))),"")) -> 0.125 | L5: =IF(ISBLANK(National_Annual!L4),"",IFERROR(IF(MAX(National_Annual!$F$4:$AD$4)=MIN(National_Annual!$F$4:$AD$4),0,(National_Annual!L4-MIN(National_Annual!$F$4:$AD$4))/(MAX(National_Annual!$F$4:$AD$4)-MIN(National_Annual!$F$4:$AD$4))),"")) -> 0.225 | M5: =IF(ISBLANK(National_Annual!M4),"",IFERROR(IF(MAX(National_Annual!$F$4:$AD$4)=MIN(National_Annual!$F$4:$AD$4),0,(National_Annual!M4-MIN(National_Annual!$F$4:$AD$4))/(MAX(National_Annual!$F$4:$AD$4)-MIN(National_Annual!$F$4:$AD$4))),"")) -> 0.325 | ... AD5: =IF(ISBLANK(National_Annual!AD4),"",IFERROR(IF(MAX(National_Annual!$F$4:$AD$4)=MIN(National_Annual!$F$4:$AD$4),0,(National_Annual!AD4-MIN(National_Annual!$F$4:$AD$4))/(MAX(National_Annual!$F$4:$AD$4)-MIN(National_Annual!$F$4:$AD$4))),"")) -> 0.975
A6: TEMP_ANOM | B6: Temperature anomaly vs 1961–1990 baseline | C6: °C | D6: V | E6: E | F6: =IF(ISBLANK(National_Annual!F5),"",IFERROR(IF(MAX(National_Annual!$F$5:$AD$5)=MIN(National_Annual!$F$5:$AD$5),0,(National_Annual!F5-MIN(National_Annual!$F$5:$AD$5))/(MAX(National_Annual!$F$5:$AD$5)-MIN(National_Annual!$F$5:$AD$5))),"")) -> 0 | G6: =IF(ISBLANK(National_Annual!G5),"",IFERROR(IF(MAX(National_Annual!$F$5:$AD$5)=MIN(National_Annual!$F$5:$AD$5),0,(National_Annual!G5-MIN(National_Annual!$F$5:$AD$5))/(MAX(National_Annual!$F$5:$AD$5)-MIN(National_Annual!$F$5:$AD$5))),"")) -> 0.175 | H6: =IF(ISBLANK(National_Annual!H5),"",IFERROR(IF(MAX(National_Annual!$F$5:$AD$5)=MIN(National_Annual!$F$5:$AD$5),0,(National_Annual!H5-MIN(National_Annual!$F$5:$AD$5))/(MAX(National_Annual!$F$5:$AD$5)-MIN(National_Annual!$F$5:$AD$5))),"")) -> 0.1 | I6: =IF(ISBLANK(National_Annual!I5),"",IFERROR(IF(MAX(National_Annual!$F$5:$AD$5)=MIN(National_Annual!$F$5:$AD$5),0,(National_Annual!I5-MIN(National_Annual!$F$5:$AD$5))/(MAX(National_Annual!$F$5:$AD$5)-MIN(National_Annual!$F$5:$AD$5))),"")) -> 0.425 | J6: =IF(ISBLANK(National_Annual!J5),"",IFERROR(IF(MAX(National_Annual!$F$5:$AD$5)=MIN(National_Annual!$F$5:$AD$5),0,(National_Annual!J5-MIN(National_Annual!$F$5:$AD$5))/(MAX(National_Annual!$F$5:$AD$5)-MIN(National_Annual!$F$5:$AD$5))),"")) -> 0.05 | K6: =IF(ISBLANK(National_Annual!K5),"",IFERROR(IF(MAX(National_Annual!$F$5:$AD$5)=MIN(National_Annual!$F$5:$AD$5),0,(National_Annual!K5-MIN(National_Annual!$F$5:$AD$5))/(MAX(National_Annual!$F$5:$AD$5)-MIN(National_Annual!$F$5:$AD$5))),"")) -> 0.125 | L6: =IF(ISBLANK(National_Annual!L5),"",IFERROR(IF(MAX(National_Annual!$F$5:$AD$5)=MIN(National_Annual!$F$5:$AD$5),0,(National_Annual!L5-MIN(National_Annual!$F$5:$AD$5))/(MAX(National_Annual!$F$5:$AD$5)-MIN(National_Annual!$F$5:$AD$5))),"")) -> 0.225 | M6: =IF(ISBLANK(National_Annual!M5),"",IFERROR(IF(MAX(National_Annual!$F$5:$AD$5)=MIN(National_Annual!$F$5:$AD$5),0,(National_Annual!M5-MIN(National_Annual!$F$5:$AD$5))/(MAX(National_Annual!$F$5:$AD$5)-MIN(National_Annual!$F$5:$AD$5))),"")) -> 0.325 | ... AD6: =IF(ISBLANK(National_Annual!AD5),"",IFERROR(IF(MAX(National_Annual!$F$5:$AD$5)=MIN(National_Annual!$F$5:$AD$5),0,(National_Annual!AD5-MIN(National_Annual!$F$5:$AD$5))/(MAX(National_Annual!$F$5:$AD$5)-MIN(National_Annual!$F$5:$AD$5))),"")) -> 0.975
A7: PRECIP | B7: Mean annual precipitation | C7: mm | D7: C | E7: E | F7: =IF(ISBLANK(National_Annual!F6),"",IFERROR(IF(MAX(National_Annual!$F$6:$AD$6)=MIN(National_Annual!$F$6:$AD$6),0,(MAX(National_Annual!$F$6:$AD$6)-National_Annual!F6)/(MAX(National_Annual!$F$6:$AD$6)-MIN(National_Annual!$F$6:$AD$6))),"")) -> 0.55555556 | G7: =IF(ISBLANK(National_Annual!G6),"",IFERROR(IF(MAX(National_Annual!$F$6:$AD$6)=MIN(National_Annual!$F$6:$AD$6),0,(MAX(National_Annual!$F$6:$AD$6)-National_Annual!G6)/(MAX(National_Annual!$F$6:$AD$6)-MIN(National_Annual!$F$6:$AD$6))),"")) -> 0.47222222 | H7: =IF(ISBLANK(National_Annual!H6),"",IFERROR(IF(MAX(National_Annual!$F$6:$AD$6)=MIN(National_Annual!$F$6:$AD$6),0,(MAX(National_Annual!$F$6:$AD$6)-National_Annual!H6)/(MAX(National_Annual!$F$6:$AD$6)-MIN(National_Annual!$F$6:$AD$6))),"")) -> 0.30555556 | I7: =IF(ISBLANK(National_Annual!I6),"",IFERROR(IF(MAX(National_Annual!$F$6:$AD$6)=MIN(National_Annual!$F$6:$AD$6),0,(MAX(National_Annual!$F$6:$AD$6)-National_Annual!I6)/(MAX(National_Annual!$F$6:$AD$6)-MIN(National_Annual!$F$6:$AD$6))),"")) -> 0.22222222 | J7: =IF(ISBLANK(National_Annual!J6),"",IFERROR(IF(MAX(National_Annual!$F$6:$AD$6)=MIN(National_Annual!$F$6:$AD$6),0,(MAX(National_Annual!$F$6:$AD$6)-National_Annual!J6)/(MAX(National_Annual!$F$6:$AD$6)-MIN(National_Annual!$F$6:$AD$6))),"")) -> 0.38888889 | K7: =IF(ISBLANK(National_Annual!K6),"",IFERROR(IF(MAX(National_Annual!$F$6:$AD$6)=MIN(National_Annual!$F$6:$AD$6),0,(MAX(National_Annual!$F$6:$AD$6)-National_Annual!K6)/(MAX(National_Annual!$F$6:$AD$6)-MIN(National_Annual!$F$6:$AD$6))),"")) -> 0.63888889 | L7: =IF(ISBLANK(National_Annual!L6),"",IFERROR(IF(MAX(National_Annual!$F$6:$AD$6)=MIN(National_Annual!$F$6:$AD$6),0,(MAX(National_Annual!$F$6:$AD$6)-National_Annual!L6)/(MAX(National_Annual!$F$6:$AD$6)-MIN(National_Annual!$F$6:$AD$6))),"")) -> 0.36111111 | M7: =IF(ISBLANK(National_Annual!M6),"",IFERROR(IF(MAX(National_Annual!$F$6:$AD$6)=MIN(National_Annual!$F$6:$AD$6),0,(MAX(National_Annual!$F$6:$AD$6)-National_Annual!M6)/(MAX(National_Annual!$F$6:$AD$6)-MIN(National_Annual!$F$6:$AD$6))),"")) -> 0.52777778 | ... AD7: =IF(ISBLANK(National_Annual!AD6),"",IFERROR(IF(MAX(National_Annual!$F$6:$AD$6)=MIN(National_Annual!$F$6:$AD$6),0,(MAX(National_Annual!$F$6:$AD$6)-National_Annual!AD6)/(MAX(National_Annual!$F$6:$AD$6)-MIN(National_Annual!$F$6:$AD$6))),"")) -> 0.91666667
A8: SPEI_PROXY | B8: Drought proxy (precip z-score, 2000–24) | C8: z-score | D8: C | E8: E | F8: =IF(ISBLANK(National_Annual!F7),"",IFERROR(IF(MAX(National_Annual!$F$7:$AD$7)=MIN(National_Annual!$F$7:$AD$7),0,(MAX(National_Annual!$F$7:$AD$7)-National_Annual!F7)/(MAX(National_Annual!$F$7:$AD$7)-MIN(National_Annual!$F$7:$AD$7))),"")) -> 0.55614973 | G8: =IF(ISBLANK(National_Annual!G7),"",IFERROR(IF(MAX(National_Annual!$F$7:$AD$7)=MIN(National_Annual!$F$7:$AD$7),0,(MAX(National_Annual!$F$7:$AD$7)-National_Annual!G7)/(MAX(National_Annual!$F$7:$AD$7)-MIN(National_Annual!$F$7:$AD$7))),"")) -> 0.47326203 | H8: =IF(ISBLANK(National_Annual!H7),"",IFERROR(IF(MAX(National_Annual!$F$7:$AD$7)=MIN(National_Annual!$F$7:$AD$7),0,(MAX(National_Annual!$F$7:$AD$7)-National_Annual!H7)/(MAX(National_Annual!$F$7:$AD$7)-MIN(National_Annual!$F$7:$AD$7))),"")) -> 0.30481283 | I8: =IF(ISBLANK(National_Annual!I7),"",IFERROR(IF(MAX(National_Annual!$F$7:$AD$7)=MIN(National_Annual!$F$7:$AD$7),0,(MAX(National_Annual!$F$7:$AD$7)-National_Annual!I7)/(MAX(National_Annual!$F$7:$AD$7)-MIN(National_Annual!$F$7:$AD$7))),"")) -> 0.22192513 | J8: =IF(ISBLANK(National_Annual!J7),"",IFERROR(IF(MAX(National_Annual!$F$7:$AD$7)=MIN(National_Annual!$F$7:$AD$7),0,(MAX(National_Annual!$F$7:$AD$7)-National_Annual!J7)/(MAX(National_Annual!$F$7:$AD$7)-MIN(National_Annual!$F$7:$AD$7))),"")) -> 0.39037433 | K8: =IF(ISBLANK(National_Annual!K7),"",IFERROR(IF(MAX(National_Annual!$F$7:$AD$7)=MIN(National_Annual!$F$7:$AD$7),0,(MAX(National_Annual!$F$7:$AD$7)-National_Annual!K7)/(MAX(National_Annual!$F$7:$AD$7)-MIN(National_Annual!$F$7:$AD$7))),"")) -> 0.63903743 | L8: =IF(ISBLANK(National_Annual!L7),"",IFERROR(IF(MAX(National_Annual!$F$7:$AD$7)=MIN(National_Annual!$F$7:$AD$7),0,(MAX(National_Annual!$F$7:$AD$7)-National_Annual!L7)/(MAX(National_Annual!$F$7:$AD$7)-MIN(National_Annual!$F$7:$AD$7))),"")) -> 0.36096257 | M8: =IF(ISBLANK(National_Annual!M7),"",IFERROR(IF(MAX(National_Annual!$F$7:$AD$7)=MIN(National_Annual!$F$7:$AD$7),0,(MAX(National_Annual!$F$7:$AD$7)-National_Annual!M7)/(MAX(National_Annual!$F$7:$AD$7)-MIN(National_Annual!$F$7:$AD$7))),"")) -> 0.52941176 | ... AD8: =IF(ISBLANK(National_Annual!AD7),"",IFERROR(IF(MAX(National_Annual!$F$7:$AD$7)=MIN(National_Annual!$F$7:$AD$7),0,(MAX(National_Annual!$F$7:$AD$7)-National_Annual!AD7)/(MAX(National_Annual!$F$7:$AD$7)-MIN(National_Annual!$F$7:$AD$7))),"")) -> 0.9171123
A9: HEATWAVE_DAYS | B9: Heatwave days (>35 °C, national avg) | C9: days | D9: V | E9: E | F9: =IF(ISBLANK(National_Annual!F8),"",IFERROR(IF(MAX(National_Annual!$F$8:$AD$8)=MIN(National_Annual!$F$8:$AD$8),0,(National_Annual!F8-MIN(National_Annual!$F$8:$AD$8))/(MAX(National_Annual!$F$8:$AD$8)-MIN(National_Annual!$F$8:$AD$8))),"")) -> 0 | G9: =IF(ISBLANK(National_Annual!G8),"",IFERROR(IF(MAX(National_Annual!$F$8:$AD$8)=MIN(National_Annual!$F$8:$AD$8),0,(National_Annual!G8-MIN(National_Annual!$F$8:$AD$8))/(MAX(National_Annual!$F$8:$AD$8)-MIN(National_Annual!$F$8:$AD$8))),"")) -> 0.085106383 | H9: =IF(ISBLANK(National_Annual!H8),"",IFERROR(IF(MAX(National_Annual!$F$8:$AD$8)=MIN(National_Annual!$F$8:$AD$8),0,(National_Annual!H8-MIN(National_Annual!$F$8:$AD$8))/(MAX(National_Annual!$F$8:$AD$8)-MIN(National_Annual!$F$8:$AD$8))),"")) -> 0.042553191 | I9: =IF(ISBLANK(National_Annual!I8),"",IFERROR(IF(MAX(National_Annual!$F$8:$AD$8)=MIN(National_Annual!$F$8:$AD$8),0,(National_Annual!I8-MIN(National_Annual!$F$8:$AD$8))/(MAX(National_Annual!$F$8:$AD$8)-MIN(National_Annual!$F$8:$AD$8))),"")) -> 0.42553191 | J9: =IF(ISBLANK(National_Annual!J8),"",IFERROR(IF(MAX(National_Annual!$F$8:$AD$8)=MIN(National_Annual!$F$8:$AD$8),0,(National_Annual!J8-MIN(National_Annual!$F$8:$AD$8))/(MAX(National_Annual!$F$8:$AD$8)-MIN(National_Annual!$F$8:$AD$8))),"")) -> 0.063829787 | K9: =IF(ISBLANK(National_Annual!K8),"",IFERROR(IF(MAX(National_Annual!$F$8:$AD$8)=MIN(National_Annual!$F$8:$AD$8),0,(National_Annual!K8-MIN(National_Annual!$F$8:$AD$8))/(MAX(National_Annual!$F$8:$AD$8)-MIN(National_Annual!$F$8:$AD$8))),"")) -> 0.14893617 | L9: =IF(ISBLANK(National_Annual!L8),"",IFERROR(IF(MAX(National_Annual!$F$8:$AD$8)=MIN(National_Annual!$F$8:$AD$8),0,(National_Annual!L8-MIN(National_Annual!$F$8:$AD$8))/(MAX(National_Annual!$F$8:$AD$8)-MIN(National_Annual!$F$8:$AD$8))),"")) -> 0.19148936 | M9: =IF(ISBLANK(National_Annual!M8),"",IFERROR(IF(MAX(National_Annual!$F$8:$AD$8)=MIN(National_Annual!$F$8:$AD$8),0,(National_Annual!M8-MIN(National_Annual!$F$8:$AD$8))/(MAX(National_Annual!$F$8:$AD$8)-MIN(National_Annual!$F$8:$AD$8))),"")) -> 0.25531915 | ... AD9: =IF(ISBLANK(National_Annual!AD8),"",IFERROR(IF(MAX(National_Annual!$F$8:$AD$8)=MIN(National_Annual!$F$8:$AD$8),0,(National_Annual!AD8-MIN(National_Annual!$F$8:$AD$8))/(MAX(National_Annual!$F$8:$AD$8)-MIN(National_Annual!$F$8:$AD$8))),"")) -> 0.89361702
A10: AGRI_GDP | B10: Agriculture, value added | C10: % GDP | D10: V | E10: S | F10: =IF(ISBLANK(National_Annual!F9),"",IFERROR(IF(MAX(National_Annual!$F$9:$AD$9)=MIN(National_Annual!$F$9:$AD$9),0,(National_Annual!F9-MIN(National_Annual!$F$9:$AD$9))/(MAX(National_Annual!$F$9:$AD$9)-MIN(National_Annual!$F$9:$AD$9))),"")) -> 0.69491525 | G10: =IF(ISBLANK(National_Annual!G9),"",IFERROR(IF(MAX(National_Annual!$F$9:$AD$9)=MIN(National_Annual!$F$9:$AD$9),0,(National_Annual!G9-MIN(National_Annual!$F$9:$AD$9))/(MAX(National_Annual!$F$9:$AD$9)-MIN(National_Annual!$F$9:$AD$9))),"")) -> 0.79661017 | H10: =IF(ISBLANK(National_Annual!H9),"",IFERROR(IF(MAX(National_Annual!$F$9:$AD$9)=MIN(National_Annual!$F$9:$AD$9),0,(National_Annual!H9-MIN(National_Annual!$F$9:$AD$9))/(MAX(National_Annual!$F$9:$AD$9)-MIN(National_Annual!$F$9:$AD$9))),"")) -> 0.89830508 | I10: =IF(ISBLANK(National_Annual!I9),"",IFERROR(IF(MAX(National_Annual!$F$9:$AD$9)=MIN(National_Annual!$F$9:$AD$9),0,(National_Annual!I9-MIN(National_Annual!$F$9:$AD$9))/(MAX(National_Annual!$F$9:$AD$9)-MIN(National_Annual!$F$9:$AD$9))),"")) -> 1 | J10: =IF(ISBLANK(National_Annual!J9),"",IFERROR(IF(MAX(National_Annual!$F$9:$AD$9)=MIN(National_Annual!$F$9:$AD$9),0,(National_Annual!J9-MIN(National_Annual!$F$9:$AD$9))/(MAX(National_Annual!$F$9:$AD$9)-MIN(National_Annual!$F$9:$AD$9))),"")) -> 0.6779661 | K10: =IF(ISBLANK(National_Annual!K9),"",IFERROR(IF(MAX(National_Annual!$F$9:$AD$9)=MIN(National_Annual!$F$9:$AD$9),0,(National_Annual!K9-MIN(National_Annual!$F$9:$AD$9))/(MAX(National_Annual!$F$9:$AD$9)-MIN(National_Annual!$F$9:$AD$9))),"")) -> 0.42372881 | L10: =IF(ISBLANK(National_Annual!L9),"",IFERROR(IF(MAX(National_Annual!$F$9:$AD$9)=MIN(National_Annual!$F$9:$AD$9),0,(National_Annual!L9-MIN(National_Annual!$F$9:$AD$9))/(MAX(National_Annual!$F$9:$AD$9)-MIN(National_Annual!$F$9:$AD$9))),"")) -> 0.83050847 | M10: =IF(ISBLANK(National_Annual!M9),"",IFERROR(IF(MAX(National_Annual!$F$9:$AD$9)=MIN(National_Annual!$F$9:$AD$9),0,(National_Annual!M9-MIN(National_Annual!$F$9:$AD$9))/(MAX(National_Annual!$F$9:$AD$9)-MIN(National_Annual!$F$9:$AD$9))),"")) -> 0.22033898 | ... AD10: =IF(ISBLANK(National_Annual!AD9),"",IFERROR(IF(MAX(National_Annual!$F$9:$AD$9)=MIN(National_Annual!$F$9:$AD$9),0,(National_Annual!AD9-MIN(National_Annual!$F$9:$AD$9))/(MAX(National_Annual!$F$9:$AD$9)-MIN(National_Annual!$F$9:$AD$9))),"")) -> 0.084745763
A11: AGRI_EMP | B11: Agriculture employment | C11: % total | D11: V | E11: S | F11: =IF(ISBLANK(National_Annual!F10),"",IFERROR(IF(MAX(National_Annual!$F$10:$AD$10)=MIN(National_Annual!$F$10:$AD$10),0,(National_Annual!F10-MIN(National_Annual!$F$10:$AD$10))/(MAX(National_Annual!$F$10:$AD$10)-MIN(National_Annual!$F$10:$AD$10))),"")) -> 1 | G11: =IF(ISBLANK(National_Annual!G10),"",IFERROR(IF(MAX(National_Annual!$F$10:$AD$10)=MIN(National_Annual!$F$10:$AD$10),0,(National_Annual!G10-MIN(National_Annual!$F$10:$AD$10))/(MAX(National_Annual!$F$10:$AD$10)-MIN(National_Annual!$F$10:$AD$10))),"")) -> 0.95104895 | H11: =IF(ISBLANK(National_Annual!H10),"",IFERROR(IF(MAX(National_Annual!$F$10:$AD$10)=MIN(National_Annual!$F$10:$AD$10),0,(National_Annual!H10-MIN(National_Annual!$F$10:$AD$10))/(MAX(National_Annual!$F$10:$AD$10)-MIN(National_Annual!$F$10:$AD$10))),"")) -> 0.90909091 | I11: =IF(ISBLANK(National_Annual!I10),"",IFERROR(IF(MAX(National_Annual!$F$10:$AD$10)=MIN(National_Annual!$F$10:$AD$10),0,(National_Annual!I10-MIN(National_Annual!$F$10:$AD$10))/(MAX(National_Annual!$F$10:$AD$10)-MIN(National_Annual!$F$10:$AD$10))),"")) -> 0.86013986 | J11: =IF(ISBLANK(National_Annual!J10),"",IFERROR(IF(MAX(National_Annual!$F$10:$AD$10)=MIN(National_Annual!$F$10:$AD$10),0,(National_Annual!J10-MIN(National_Annual!$F$10:$AD$10))/(MAX(National_Annual!$F$10:$AD$10)-MIN(National_Annual!$F$10:$AD$10))),"")) -> 0.81118881 | K11: =IF(ISBLANK(National_Annual!K10),"",IFERROR(IF(MAX(National_Annual!$F$10:$AD$10)=MIN(National_Annual!$F$10:$AD$10),0,(National_Annual!K10-MIN(National_Annual!$F$10:$AD$10))/(MAX(National_Annual!$F$10:$AD$10)-MIN(National_Annual!$F$10:$AD$10))),"")) -> 0.76923077 | L11: =IF(ISBLANK(National_Annual!L10),"",IFERROR(IF(MAX(National_Annual!$F$10:$AD$10)=MIN(National_Annual!$F$10:$AD$10),0,(National_Annual!L10-MIN(National_Annual!$F$10:$AD$10))/(MAX(National_Annual!$F$10:$AD$10)-MIN(National_Annual!$F$10:$AD$10))),"")) -> 0.72727273 | M11: =IF(ISBLANK(National_Annual!M10),"",IFERROR(IF(MAX(National_Annual!$F$10:$AD$10)=MIN(National_Annual!$F$10:$AD$10),0,(National_Annual!M10-MIN(National_Annual!$F$10:$AD$10))/(MAX(National_Annual!$F$10:$AD$10)-MIN(National_Annual!$F$10:$AD$10))),"")) -> 0.68531469 | ... AD11: =IF(ISBLANK(National_Annual!AD10),"",IFERROR(IF(MAX(National_Annual!$F$10:$AD$10)=MIN(National_Annual!$F$10:$AD$10),0,(National_Annual!AD10-MIN(National_Annual!$F$10:$AD$10))/(MAX(National_Annual!$F$10:$AD$10)-MIN(National_Annual!$F$10:$AD$10))),"")) -> 0
A12: WATER_PC | B12: Renewable freshwater per capita | C12: m³/person | D12: C | E12: S | F12: =IF(ISBLANK(National_Annual!F11),"",IFERROR(IF(MAX(National_Annual!$F$11:$AD$11)=MIN(National_Annual!$F$11:$AD$11),0,(MAX(National_Annual!$F$11:$AD$11)-National_Annual!F11)/(MAX(National_Annual!$F$11:$AD$11)-MIN(National_Annual!$F$11:$AD$11))),"")) -> 0 | G12: =IF(ISBLANK(National_Annual!G11),"",IFERROR(IF(MAX(National_Annual!$F$11:$AD$11)=MIN(National_Annual!$F$11:$AD$11),0,(MAX(National_Annual!$F$11:$AD$11)-National_Annual!G11)/(MAX(National_Annual!$F$11:$AD$11)-MIN(National_Annual!$F$11:$AD$11))),"")) -> 0.029411765 | H12: =IF(ISBLANK(National_Annual!H11),"",IFERROR(IF(MAX(National_Annual!$F$11:$AD$11)=MIN(National_Annual!$F$11:$AD$11),0,(MAX(National_Annual!$F$11:$AD$11)-National_Annual!H11)/(MAX(National_Annual!$F$11:$AD$11)-MIN(National_Annual!$F$11:$AD$11))),"")) -> 0.058823529 | I12: =IF(ISBLANK(National_Annual!I11),"",IFERROR(IF(MAX(National_Annual!$F$11:$AD$11)=MIN(National_Annual!$F$11:$AD$11),0,(MAX(National_Annual!$F$11:$AD$11)-National_Annual!I11)/(MAX(National_Annual!$F$11:$AD$11)-MIN(National_Annual!$F$11:$AD$11))),"")) -> 0.10294118 | J12: =IF(ISBLANK(National_Annual!J11),"",IFERROR(IF(MAX(National_Annual!$F$11:$AD$11)=MIN(National_Annual!$F$11:$AD$11),0,(MAX(National_Annual!$F$11:$AD$11)-National_Annual!J11)/(MAX(National_Annual!$F$11:$AD$11)-MIN(National_Annual!$F$11:$AD$11))),"")) -> 0.14705882 | K12: =IF(ISBLANK(National_Annual!K11),"",IFERROR(IF(MAX(National_Annual!$F$11:$AD$11)=MIN(National_Annual!$F$11:$AD$11),0,(MAX(National_Annual!$F$11:$AD$11)-National_Annual!K11)/(MAX(National_Annual!$F$11:$AD$11)-MIN(National_Annual!$F$11:$AD$11))),"")) -> 0.19117647 | L12: =IF(ISBLANK(National_Annual!L11),"",IFERROR(IF(MAX(National_Annual!$F$11:$AD$11)=MIN(National_Annual!$F$11:$AD$11),0,(MAX(National_Annual!$F$11:$AD$11)-National_Annual!L11)/(MAX(National_Annual!$F$11:$AD$11)-MIN(National_Annual!$F$11:$AD$11))),"")) -> 0.23529412 | M12: =IF(ISBLANK(National_Annual!M11),"",IFERROR(IF(MAX(National_Annual!$F$11:$AD$11)=MIN(National_Annual!$F$11:$AD$11),0,(MAX(National_Annual!$F$11:$AD$11)-National_Annual!M11)/(MAX(National_Annual!$F$11:$AD$11)-MIN(National_Annual!$F$11:$AD$11))),"")) -> 0.27941176 | ... AD12: =IF(ISBLANK(National_Annual!AD11),"",IFERROR(IF(MAX(National_Annual!$F$11:$AD$11)=MIN(National_Annual!$F$11:$AD$11),0,(MAX(National_Annual!$F$11:$AD$11)-National_Annual!AD11)/(MAX(National_Annual!$F$11:$AD$11)-MIN(National_Annual!$F$11:$AD$11))),"")) -> 1
A13: RURAL_PCT | B13: Rural population | C13: % total | D13: V | E13: S | F13: =IF(ISBLANK(National_Annual!F12),"",IFERROR(IF(MAX(National_Annual!$F$12:$AD$12)=MIN(National_Annual!$F$12:$AD$12),0,(National_Annual!F12-MIN(National_Annual!$F$12:$AD$12))/(MAX(National_Annual!$F$12:$AD$12)-MIN(National_Annual!$F$12:$AD$12))),"")) -> 1 | G13: =IF(ISBLANK(National_Annual!G12),"",IFERROR(IF(MAX(National_Annual!$F$12:$AD$12)=MIN(National_Annual!$F$12:$AD$12),0,(National_Annual!G12-MIN(National_Annual!$F$12:$AD$12))/(MAX(National_Annual!$F$12:$AD$12)-MIN(National_Annual!$F$12:$AD$12))),"")) -> 0.94520548 | H13: =IF(ISBLANK(National_Annual!H12),"",IFERROR(IF(MAX(National_Annual!$F$12:$AD$12)=MIN(National_Annual!$F$12:$AD$12),0,(National_Annual!H12-MIN(National_Annual!$F$12:$AD$12))/(MAX(National_Annual!$F$12:$AD$12)-MIN(National_Annual!$F$12:$AD$12))),"")) -> 0.89041096 | I13: =IF(ISBLANK(National_Annual!I12),"",IFERROR(IF(MAX(National_Annual!$F$12:$AD$12)=MIN(National_Annual!$F$12:$AD$12),0,(National_Annual!I12-MIN(National_Annual!$F$12:$AD$12))/(MAX(National_Annual!$F$12:$AD$12)-MIN(National_Annual!$F$12:$AD$12))),"")) -> 0.83561644 | J13: =IF(ISBLANK(National_Annual!J12),"",IFERROR(IF(MAX(National_Annual!$F$12:$AD$12)=MIN(National_Annual!$F$12:$AD$12),0,(National_Annual!J12-MIN(National_Annual!$F$12:$AD$12))/(MAX(National_Annual!$F$12:$AD$12)-MIN(National_Annual!$F$12:$AD$12))),"")) -> 0.78082192 | K13: =IF(ISBLANK(National_Annual!K12),"",IFERROR(IF(MAX(National_Annual!$F$12:$AD$12)=MIN(National_Annual!$F$12:$AD$12),0,(National_Annual!K12-MIN(National_Annual!$F$12:$AD$12))/(MAX(National_Annual!$F$12:$AD$12)-MIN(National_Annual!$F$12:$AD$12))),"")) -> 0.7260274 | L13: =IF(ISBLANK(National_Annual!L12),"",IFERROR(IF(MAX(National_Annual!$F$12:$AD$12)=MIN(National_Annual!$F$12:$AD$12),0,(National_Annual!L12-MIN(National_Annual!$F$12:$AD$12))/(MAX(National_Annual!$F$12:$AD$12)-MIN(National_Annual!$F$12:$AD$12))),"")) -> 0.67123288 | M13: =IF(ISBLANK(National_Annual!M12),"",IFERROR(IF(MAX(National_Annual!$F$12:$AD$12)=MIN(National_Annual!$F$12:$AD$12),0,(National_Annual!M12-MIN(National_Annual!$F$12:$AD$12))/(MAX(National_Annual!$F$12:$AD$12)-MIN(National_Annual!$F$12:$AD$12))),"")) -> 0.61643836 | ... AD13: =IF(ISBLANK(National_Annual!AD12),"",IFERROR(IF(MAX(National_Annual!$F$12:$AD$12)=MIN(National_Annual!$F$12:$AD$12),0,(National_Annual!AD12-MIN(National_Annual!$F$12:$AD$12))/(MAX(National_Annual!$F$12:$AD$12)-MIN(National_Annual!$F$12:$AD$12))),"")) -> 0
A14: GDP_PC_PPP | B14: GDP per capita, PPP | C14: int$ | D14: C | E14: AC_SE | F14: =IF(ISBLANK(National_Annual!F13),"",IFERROR(IF(MAX(National_Annual!$F$13:$AD$13)=MIN(National_Annual!$F$13:$AD$13),0,(MAX(National_Annual!$F$13:$AD$13)-National_Annual!F13)/(MAX(National_Annual!$F$13:$AD$13)-MIN(National_Annual!$F$13:$AD$13))),"")) -> 1 | G14: =IF(ISBLANK(National_Annual!G13),"",IFERROR(IF(MAX(National_Annual!$F$13:$AD$13)=MIN(National_Annual!$F$13:$AD$13),0,(MAX(National_Annual!$F$13:$AD$13)-National_Annual!G13)/(MAX(National_Annual!$F$13:$AD$13)-MIN(National_Annual!$F$13:$AD$13))),"")) -> 0.97548666 | H14: =IF(ISBLANK(National_Annual!H13),"",IFERROR(IF(MAX(National_Annual!$F$13:$AD$13)=MIN(National_Annual!$F$13:$AD$13),0,(MAX(National_Annual!$F$13:$AD$13)-National_Annual!H13)/(MAX(National_Annual!$F$13:$AD$13)-MIN(National_Annual!$F$13:$AD$13))),"")) -> 0.95674117 | I14: =IF(ISBLANK(National_Annual!I13),"",IFERROR(IF(MAX(National_Annual!$F$13:$AD$13)=MIN(National_Annual!$F$13:$AD$13),0,(MAX(National_Annual!$F$13:$AD$13)-National_Annual!I13)/(MAX(National_Annual!$F$13:$AD$13)-MIN(National_Annual!$F$13:$AD$13))),"")) -> 0.91780822 | J14: =IF(ISBLANK(National_Annual!J13),"",IFERROR(IF(MAX(National_Annual!$F$13:$AD$13)=MIN(National_Annual!$F$13:$AD$13),0,(MAX(National_Annual!$F$13:$AD$13)-National_Annual!J13)/(MAX(National_Annual!$F$13:$AD$13)-MIN(National_Annual!$F$13:$AD$13))),"")) -> 0.88464311 | K14: =IF(ISBLANK(National_Annual!K13),"",IFERROR(IF(MAX(National_Annual!$F$13:$AD$13)=MIN(National_Annual!$F$13:$AD$13),0,(MAX(National_Annual!$F$13:$AD$13)-National_Annual!K13)/(MAX(National_Annual!$F$13:$AD$13)-MIN(National_Annual!$F$13:$AD$13))),"")) -> 0.86157174 | L14: =IF(ISBLANK(National_Annual!L13),"",IFERROR(IF(MAX(National_Annual!$F$13:$AD$13)=MIN(National_Annual!$F$13:$AD$13),0,(MAX(National_Annual!$F$13:$AD$13)-National_Annual!L13)/(MAX(National_Annual!$F$13:$AD$13)-MIN(National_Annual!$F$13:$AD$13))),"")) -> 0.82408075 | M14: =IF(ISBLANK(National_Annual!M13),"",IFERROR(IF(MAX(National_Annual!$F$13:$AD$13)=MIN(National_Annual!$F$13:$AD$13),0,(MAX(National_Annual!$F$13:$AD$13)-National_Annual!M13)/(MAX(National_Annual!$F$13:$AD$13)-MIN(National_Annual!$F$13:$AD$13))),"")) -> 0.78370584 | ... AD14: =IF(ISBLANK(National_Annual!AD13),"",IFERROR(IF(MAX(National_Annual!$F$13:$AD$13)=MIN(National_Annual!$F$13:$AD$13),0,(MAX(National_Annual!$F$13:$AD$13)-National_Annual!AD13)/(MAX(National_Annual!$F$13:$AD$13)-MIN(National_Annual!$F$13:$AD$13))),"")) -> 0
A15: HDI | B15: Human Development Index | C15: 0–1 | D15: C | E15: AC_SE | F15: =IF(ISBLANK(National_Annual!F14),"",IFERROR(IF(MAX(National_Annual!$F$14:$AD$14)=MIN(National_Annual!$F$14:$AD$14),0,(MAX(National_Annual!$F$14:$AD$14)-National_Annual!F14)/(MAX(National_Annual!$F$14:$AD$14)-MIN(National_Annual!$F$14:$AD$14))),"")) -> 1 | G15: =IF(ISBLANK(National_Annual!G14),"",IFERROR(IF(MAX(National_Annual!$F$14:$AD$14)=MIN(National_Annual!$F$14:$AD$14),0,(MAX(National_Annual!$F$14:$AD$14)-National_Annual!G14)/(MAX(National_Annual!$F$14:$AD$14)-MIN(National_Annual!$F$14:$AD$14))),"")) -> 0.94594595 | H15: =IF(ISBLANK(National_Annual!H14),"",IFERROR(IF(MAX(National_Annual!$F$14:$AD$14)=MIN(National_Annual!$F$14:$AD$14),0,(MAX(National_Annual!$F$14:$AD$14)-National_Annual!H14)/(MAX(National_Annual!$F$14:$AD$14)-MIN(National_Annual!$F$14:$AD$14))),"")) -> 0.91891892 | I15: =IF(ISBLANK(National_Annual!I14),"",IFERROR(IF(MAX(National_Annual!$F$14:$AD$14)=MIN(National_Annual!$F$14:$AD$14),0,(MAX(National_Annual!$F$14:$AD$14)-National_Annual!I14)/(MAX(National_Annual!$F$14:$AD$14)-MIN(National_Annual!$F$14:$AD$14))),"")) -> 0.86486486 | J15: =IF(ISBLANK(National_Annual!J14),"",IFERROR(IF(MAX(National_Annual!$F$14:$AD$14)=MIN(National_Annual!$F$14:$AD$14),0,(MAX(National_Annual!$F$14:$AD$14)-National_Annual!J14)/(MAX(National_Annual!$F$14:$AD$14)-MIN(National_Annual!$F$14:$AD$14))),"")) -> 0.81081081 | K15: =IF(ISBLANK(National_Annual!K14),"",IFERROR(IF(MAX(National_Annual!$F$14:$AD$14)=MIN(National_Annual!$F$14:$AD$14),0,(MAX(National_Annual!$F$14:$AD$14)-National_Annual!K14)/(MAX(National_Annual!$F$14:$AD$14)-MIN(National_Annual!$F$14:$AD$14))),"")) -> 0.75675676 | L15: =IF(ISBLANK(National_Annual!L14),"",IFERROR(IF(MAX(National_Annual!$F$14:$AD$14)=MIN(National_Annual!$F$14:$AD$14),0,(MAX(National_Annual!$F$14:$AD$14)-National_Annual!L14)/(MAX(National_Annual!$F$14:$AD$14)-MIN(National_Annual!$F$14:$AD$14))),"")) -> 0.7027027 | M15: =IF(ISBLANK(National_Annual!M14),"",IFERROR(IF(MAX(National_Annual!$F$14:$AD$14)=MIN(National_Annual!$F$14:$AD$14),0,(MAX(National_Annual!$F$14:$AD$14)-National_Annual!M14)/(MAX(National_Annual!$F$14:$AD$14)-MIN(National_Annual!$F$14:$AD$14))),"")) -> 0.64864865 | ... AD15: =IF(ISBLANK(National_Annual!AD14),"",IFERROR(IF(MAX(National_Annual!$F$14:$AD$14)=MIN(National_Annual!$F$14:$AD$14),0,(MAX(National_Annual!$F$14:$AD$14)-National_Annual!AD14)/(MAX(National_Annual!$F$14:$AD$14)-MIN(National_Annual!$F$14:$AD$14))),"")) -> 0
A16: GOV_EFF | B16: Government Effectiveness percentile | C16: 0–100 | D16: C | E16: AC_SE | F16: =IF(ISBLANK(National_Annual!F15),"",IFERROR(IF(MAX(National_Annual!$F$15:$AD$15)=MIN(National_Annual!$F$15:$AD$15),0,(MAX(National_Annual!$F$15:$AD$15)-National_Annual!F15)/(MAX(National_Annual!$F$15:$AD$15)-MIN(National_Annual!$F$15:$AD$15))),"")) -> 0 | G16: =IF(ISBLANK(National_Annual!G15),"",IFERROR(IF(MAX(National_Annual!$F$15:$AD$15)=MIN(National_Annual!$F$15:$AD$15),0,(MAX(National_Annual!$F$15:$AD$15)-National_Annual!G15)/(MAX(National_Annual!$F$15:$AD$15)-MIN(National_Annual!$F$15:$AD$15))),"")) -> 0.16666667 | H16: =IF(ISBLANK(National_Annual!H15),"",IFERROR(IF(MAX(National_Annual!$F$15:$AD$15)=MIN(National_Annual!$F$15:$AD$15),0,(MAX(National_Annual!$F$15:$AD$15)-National_Annual!H15)/(MAX(National_Annual!$F$15:$AD$15)-MIN(National_Annual!$F$15:$AD$15))),"")) -> 0.33333333 | I16: =IF(ISBLANK(National_Annual!I15),"",IFERROR(IF(MAX(National_Annual!$F$15:$AD$15)=MIN(National_Annual!$F$15:$AD$15),0,(MAX(National_Annual!$F$15:$AD$15)-National_Annual!I15)/(MAX(National_Annual!$F$15:$AD$15)-MIN(National_Annual!$F$15:$AD$15))),"")) -> 0.5 | J16: =IF(ISBLANK(National_Annual!J15),"",IFERROR(IF(MAX(National_Annual!$F$15:$AD$15)=MIN(National_Annual!$F$15:$AD$15),0,(MAX(National_Annual!$F$15:$AD$15)-National_Annual!J15)/(MAX(National_Annual!$F$15:$AD$15)-MIN(National_Annual!$F$15:$AD$15))),"")) -> 0.33333333 | K16: =IF(ISBLANK(National_Annual!K15),"",IFERROR(IF(MAX(National_Annual!$F$15:$AD$15)=MIN(National_Annual!$F$15:$AD$15),0,(MAX(National_Annual!$F$15:$AD$15)-National_Annual!K15)/(MAX(National_Annual!$F$15:$AD$15)-MIN(National_Annual!$F$15:$AD$15))),"")) -> 0 | L16: =IF(ISBLANK(National_Annual!L15),"",IFERROR(IF(MAX(National_Annual!$F$15:$AD$15)=MIN(National_Annual!$F$15:$AD$15),0,(MAX(National_Annual!$F$15:$AD$15)-National_Annual!L15)/(MAX(National_Annual!$F$15:$AD$15)-MIN(National_Annual!$F$15:$AD$15))),"")) -> 0.16666667 | M16: =IF(ISBLANK(National_Annual!M15),"",IFERROR(IF(MAX(National_Annual!$F$15:$AD$15)=MIN(National_Annual!$F$15:$AD$15),0,(MAX(National_Annual!$F$15:$AD$15)-National_Annual!M15)/(MAX(National_Annual!$F$15:$AD$15)-MIN(National_Annual!$F$15:$AD$15))),"")) -> 0.33333333 | ... AD16: =IF(ISBLANK(National_Annual!AD15),"",IFERROR(IF(MAX(National_Annual!$F$15:$AD$15)=MIN(National_Annual!$F$15:$AD$15),0,(MAX(National_Annual!$F$15:$AD$15)-National_Annual!AD15)/(MAX(National_Annual!$F$15:$AD$15)-MIN(National_Annual!$F$15:$AD$15))),"")) -> 0
A17: INTERNET | B17: Individuals using the Internet | C17: % pop | D17: C | E17: AC_TECH | F17: =IF(ISBLANK(National_Annual!F16),"",IFERROR(IF(MAX(National_Annual!$F$16:$AD$16)=MIN(National_Annual!$F$16:$AD$16),0,(MAX(National_Annual!$F$16:$AD$16)-National_Annual!F16)/(MAX(National_Annual!$F$16:$AD$16)-MIN(National_Annual!$F$16:$AD$16))),"")) -> 1 | G17: =IF(ISBLANK(National_Annual!G16),"",IFERROR(IF(MAX(National_Annual!$F$16:$AD$16)=MIN(National_Annual!$F$16:$AD$16),0,(MAX(National_Annual!$F$16:$AD$16)-National_Annual!G16)/(MAX(National_Annual!$F$16:$AD$16)-MIN(National_Annual!$F$16:$AD$16))),"")) -> 0.99222222 | H17: =IF(ISBLANK(National_Annual!H16),"",IFERROR(IF(MAX(National_Annual!$F$16:$AD$16)=MIN(National_Annual!$F$16:$AD$16),0,(MAX(National_Annual!$F$16:$AD$16)-National_Annual!H16)/(MAX(National_Annual!$F$16:$AD$16)-MIN(National_Annual!$F$16:$AD$16))),"")) -> 0.98111111 | I17: =IF(ISBLANK(National_Annual!I16),"",IFERROR(IF(MAX(National_Annual!$F$16:$AD$16)=MIN(National_Annual!$F$16:$AD$16),0,(MAX(National_Annual!$F$16:$AD$16)-National_Annual!I16)/(MAX(National_Annual!$F$16:$AD$16)-MIN(National_Annual!$F$16:$AD$16))),"")) -> 0.97 | J17: =IF(ISBLANK(National_Annual!J16),"",IFERROR(IF(MAX(National_Annual!$F$16:$AD$16)=MIN(National_Annual!$F$16:$AD$16),0,(MAX(National_Annual!$F$16:$AD$16)-National_Annual!J16)/(MAX(National_Annual!$F$16:$AD$16)-MIN(National_Annual!$F$16:$AD$16))),"")) -> 0.87888889 | K17: =IF(ISBLANK(National_Annual!K16),"",IFERROR(IF(MAX(National_Annual!$F$16:$AD$16)=MIN(National_Annual!$F$16:$AD$16),0,(MAX(National_Annual!$F$16:$AD$16)-National_Annual!K16)/(MAX(National_Annual!$F$16:$AD$16)-MIN(National_Annual!$F$16:$AD$16))),"")) -> 0.84111111 | L17: =IF(ISBLANK(National_Annual!L16),"",IFERROR(IF(MAX(National_Annual!$F$16:$AD$16)=MIN(National_Annual!$F$16:$AD$16),0,(MAX(National_Annual!$F$16:$AD$16)-National_Annual!L16)/(MAX(National_Annual!$F$16:$AD$16)-MIN(National_Annual!$F$16:$AD$16))),"")) -> 0.79111111 | M17: =IF(ISBLANK(National_Annual!M16),"",IFERROR(IF(MAX(National_Annual!$F$16:$AD$16)=MIN(National_Annual!$F$16:$AD$16),0,(MAX(National_Annual!$F$16:$AD$16)-National_Annual!M16)/(MAX(National_Annual!$F$16:$AD$16)-MIN(National_Annual!$F$16:$AD$16))),"")) -> 0.76888889 | ... AD17: =IF(ISBLANK(National_Annual!AD16),"",IFERROR(IF(MAX(National_Annual!$F$16:$AD$16)=MIN(National_Annual!$F$16:$AD$16),0,(MAX(National_Annual!$F$16:$AD$16)-National_Annual!AD16)/(MAX(National_Annual!$F$16:$AD$16)-MIN(National_Annual!$F$16:$AD$16))),"")) -> 0
A18: MOBILE | B18: Mobile cellular subscriptions | C18: per 100 pop | D18: C | E18: AC_TECH | F18: =IF(ISBLANK(National_Annual!F17),"",IFERROR(IF(MAX(National_Annual!$F$17:$AD$17)=MIN(National_Annual!$F$17:$AD$17),0,(MAX(National_Annual!$F$17:$AD$17)-National_Annual!F17)/(MAX(National_Annual!$F$17:$AD$17)-MIN(National_Annual!$F$17:$AD$17))),"")) -> 1 | G18: =IF(ISBLANK(National_Annual!G17),"",IFERROR(IF(MAX(National_Annual!$F$17:$AD$17)=MIN(National_Annual!$F$17:$AD$17),0,(MAX(National_Annual!$F$17:$AD$17)-National_Annual!G17)/(MAX(National_Annual!$F$17:$AD$17)-MIN(National_Annual!$F$17:$AD$17))),"")) -> 0.94460432 | H18: =IF(ISBLANK(National_Annual!H17),"",IFERROR(IF(MAX(National_Annual!$F$17:$AD$17)=MIN(National_Annual!$F$17:$AD$17),0,(MAX(National_Annual!$F$17:$AD$17)-National_Annual!H17)/(MAX(National_Annual!$F$17:$AD$17)-MIN(National_Annual!$F$17:$AD$17))),"")) -> 0.90647482 | I18: =IF(ISBLANK(National_Annual!I17),"",IFERROR(IF(MAX(National_Annual!$F$17:$AD$17)=MIN(National_Annual!$F$17:$AD$17),0,(MAX(National_Annual!$F$17:$AD$17)-National_Annual!I17)/(MAX(National_Annual!$F$17:$AD$17)-MIN(National_Annual!$F$17:$AD$17))),"")) -> 0.87769784 | J18: =IF(ISBLANK(National_Annual!J17),"",IFERROR(IF(MAX(National_Annual!$F$17:$AD$17)=MIN(National_Annual!$F$17:$AD$17),0,(MAX(National_Annual!$F$17:$AD$17)-National_Annual!J17)/(MAX(National_Annual!$F$17:$AD$17)-MIN(National_Annual!$F$17:$AD$17))),"")) -> 0.83021583 | K18: =IF(ISBLANK(National_Annual!K17),"",IFERROR(IF(MAX(National_Annual!$F$17:$AD$17)=MIN(National_Annual!$F$17:$AD$17),0,(MAX(National_Annual!$F$17:$AD$17)-National_Annual!K17)/(MAX(National_Annual!$F$17:$AD$17)-MIN(National_Annual!$F$17:$AD$17))),"")) -> 0.76258993 | L18: =IF(ISBLANK(National_Annual!L17),"",IFERROR(IF(MAX(National_Annual!$F$17:$AD$17)=MIN(National_Annual!$F$17:$AD$17),0,(MAX(National_Annual!$F$17:$AD$17)-National_Annual!L17)/(MAX(National_Annual!$F$17:$AD$17)-MIN(National_Annual!$F$17:$AD$17))),"")) -> 0.67625899 | M18: =IF(ISBLANK(National_Annual!M17),"",IFERROR(IF(MAX(National_Annual!$F$17:$AD$17)=MIN(National_Annual!$F$17:$AD$17),0,(MAX(National_Annual!$F$17:$AD$17)-National_Annual!M17)/(MAX(National_Annual!$F$17:$AD$17)-MIN(National_Annual!$F$17:$AD$17))),"")) -> 0.56115108 | ... AD18: =IF(ISBLANK(National_Annual!AD17),"",IFERROR(IF(MAX(National_Annual!$F$17:$AD$17)=MIN(National_Annual!$F$17:$AD$17),0,(MAX(National_Annual!$F$17:$AD$17)-National_Annual!AD17)/(MAX(National_Annual!$F$17:$AD$17)-MIN(National_Annual!$F$17:$AD$17))),"")) -> 0
A19: RD_GDP | B19: R&D expenditure | C19: % GDP | D19: C | E19: AC_TECH | F19: =IF(ISBLANK(National_Annual!F18),"",IFERROR(IF(MAX(National_Annual!$F$18:$AD$18)=MIN(National_Annual!$F$18:$AD$18),0,(MAX(National_Annual!$F$18:$AD$18)-National_Annual!F18)/(MAX(National_Annual!$F$18:$AD$18)-MIN(National_Annual!$F$18:$AD$18))),"")) -> 1 | G19: =IF(ISBLANK(National_Annual!G18),"",IFERROR(IF(MAX(National_Annual!$F$18:$AD$18)=MIN(National_Annual!$F$18:$AD$18),0,(MAX(National_Annual!$F$18:$AD$18)-National_Annual!G18)/(MAX(National_Annual!$F$18:$AD$18)-MIN(National_Annual!$F$18:$AD$18))),"")) -> 0.89583333 | H19: =IF(ISBLANK(National_Annual!H18),"",IFERROR(IF(MAX(National_Annual!$F$18:$AD$18)=MIN(National_Annual!$F$18:$AD$18),0,(MAX(National_Annual!$F$18:$AD$18)-National_Annual!H18)/(MAX(National_Annual!$F$18:$AD$18)-MIN(National_Annual!$F$18:$AD$18))),"")) -> 0.79166667 | I19: =IF(ISBLANK(National_Annual!I18),"",IFERROR(IF(MAX(National_Annual!$F$18:$AD$18)=MIN(National_Annual!$F$18:$AD$18),0,(MAX(National_Annual!$F$18:$AD$18)-National_Annual!I18)/(MAX(National_Annual!$F$18:$AD$18)-MIN(National_Annual!$F$18:$AD$18))),"")) -> 0.6875 | J19: =IF(ISBLANK(National_Annual!J18),"",IFERROR(IF(MAX(National_Annual!$F$18:$AD$18)=MIN(National_Annual!$F$18:$AD$18),0,(MAX(National_Annual!$F$18:$AD$18)-National_Annual!J18)/(MAX(National_Annual!$F$18:$AD$18)-MIN(National_Annual!$F$18:$AD$18))),"")) -> 0.47916667 | K19: =IF(ISBLANK(National_Annual!K18),"",IFERROR(IF(MAX(National_Annual!$F$18:$AD$18)=MIN(National_Annual!$F$18:$AD$18),0,(MAX(National_Annual!$F$18:$AD$18)-National_Annual!K18)/(MAX(National_Annual!$F$18:$AD$18)-MIN(National_Annual!$F$18:$AD$18))),"")) -> 0.375 | L19: =IF(ISBLANK(National_Annual!L18),"",IFERROR(IF(MAX(National_Annual!$F$18:$AD$18)=MIN(National_Annual!$F$18:$AD$18),0,(MAX(National_Annual!$F$18:$AD$18)-National_Annual!L18)/(MAX(National_Annual!$F$18:$AD$18)-MIN(National_Annual!$F$18:$AD$18))),"")) -> 0.33333333 | M19: =IF(ISBLANK(National_Annual!M18),"",IFERROR(IF(MAX(National_Annual!$F$18:$AD$18)=MIN(National_Annual!$F$18:$AD$18),0,(MAX(National_Annual!$F$18:$AD$18)-National_Annual!M18)/(MAX(National_Annual!$F$18:$AD$18)-MIN(National_Annual!$F$18:$AD$18))),"")) -> 0.29166667 | ... AD19: =IF(ISBLANK(National_Annual!AD18),"",IFERROR(IF(MAX(National_Annual!$F$18:$AD$18)=MIN(National_Annual!$F$18:$AD$18),0,(MAX(National_Annual!$F$18:$AD$18)-National_Annual!AD18)/(MAX(National_Annual!$F$18:$AD$18)-MIN(National_Annual!$F$18:$AD$18))),"")) -> 0
A20: RE_SHARE | B20: Renewables in electricity generation | C20: % | D20: C | E20: AC_TECH | F20: =IF(ISBLANK(National_Annual!F19),"",IFERROR(IF(MAX(National_Annual!$F$19:$AD$19)=MIN(National_Annual!$F$19:$AD$19),0,(MAX(National_Annual!$F$19:$AD$19)-National_Annual!F19)/(MAX(National_Annual!$F$19:$AD$19)-MIN(National_Annual!$F$19:$AD$19))),"")) -> 0.91145833 | G20: =IF(ISBLANK(National_Annual!G19),"",IFERROR(IF(MAX(National_Annual!$F$19:$AD$19)=MIN(National_Annual!$F$19:$AD$19),0,(MAX(National_Annual!$F$19:$AD$19)-National_Annual!G19)/(MAX(National_Annual!$F$19:$AD$19)-MIN(National_Annual!$F$19:$AD$19))),"")) -> 0.890625 | H20: =IF(ISBLANK(National_Annual!H19),"",IFERROR(IF(MAX(National_Annual!$F$19:$AD$19)=MIN(National_Annual!$F$19:$AD$19),0,(MAX(National_Annual!$F$19:$AD$19)-National_Annual!H19)/(MAX(National_Annual!$F$19:$AD$19)-MIN(National_Annual!$F$19:$AD$19))),"")) -> 0.88020833 | I20: =IF(ISBLANK(National_Annual!I19),"",IFERROR(IF(MAX(National_Annual!$F$19:$AD$19)=MIN(National_Annual!$F$19:$AD$19),0,(MAX(National_Annual!$F$19:$AD$19)-National_Annual!I19)/(MAX(National_Annual!$F$19:$AD$19)-MIN(National_Annual!$F$19:$AD$19))),"")) -> 0.86458333 | J20: =IF(ISBLANK(National_Annual!J19),"",IFERROR(IF(MAX(National_Annual!$F$19:$AD$19)=MIN(National_Annual!$F$19:$AD$19),0,(MAX(National_Annual!$F$19:$AD$19)-National_Annual!J19)/(MAX(National_Annual!$F$19:$AD$19)-MIN(National_Annual!$F$19:$AD$19))),"")) -> 0.89583333 | K20: =IF(ISBLANK(National_Annual!K19),"",IFERROR(IF(MAX(National_Annual!$F$19:$AD$19)=MIN(National_Annual!$F$19:$AD$19),0,(MAX(National_Annual!$F$19:$AD$19)-National_Annual!K19)/(MAX(National_Annual!$F$19:$AD$19)-MIN(National_Annual!$F$19:$AD$19))),"")) -> 0.92708333 | L20: =IF(ISBLANK(National_Annual!L19),"",IFERROR(IF(MAX(National_Annual!$F$19:$AD$19)=MIN(National_Annual!$F$19:$AD$19),0,(MAX(National_Annual!$F$19:$AD$19)-National_Annual!L19)/(MAX(National_Annual!$F$19:$AD$19)-MIN(National_Annual!$F$19:$AD$19))),"")) -> 0.96354167 | M20: =IF(ISBLANK(National_Annual!M19),"",IFERROR(IF(MAX(National_Annual!$F$19:$AD$19)=MIN(National_Annual!$F$19:$AD$19),0,(MAX(National_Annual!$F$19:$AD$19)-National_Annual!M19)/(MAX(National_Annual!$F$19:$AD$19)-MIN(National_Annual!$F$19:$AD$19))),"")) -> 0.98958333 | ... AD20: =IF(ISBLANK(National_Annual!AD19),"",IFERROR(IF(MAX(National_Annual!$F$19:$AD$19)=MIN(National_Annual!$F$19:$AD$19),0,(MAX(National_Annual!$F$19:$AD$19)-National_Annual!AD19)/(MAX(National_Annual!$F$19:$AD$19)-MIN(National_Annual!$F$19:$AD$19))),"")) -> 0
A21: PATENTS_PM | B21: Patent applications, residents | C21: per million pop | D21: C | E21: AC_TECH | F21: =IF(ISBLANK(National_Annual!F20),"",IFERROR(IF(MAX(National_Annual!$F$20:$AD$20)=MIN(National_Annual!$F$20:$AD$20),0,(MAX(National_Annual!$F$20:$AD$20)-National_Annual!F20)/(MAX(National_Annual!$F$20:$AD$20)-MIN(National_Annual!$F$20:$AD$20))),"")) -> 1 | G21: =IF(ISBLANK(National_Annual!G20),"",IFERROR(IF(MAX(National_Annual!$F$20:$AD$20)=MIN(National_Annual!$F$20:$AD$20),0,(MAX(National_Annual!$F$20:$AD$20)-National_Annual!G20)/(MAX(National_Annual!$F$20:$AD$20)-MIN(National_Annual!$F$20:$AD$20))),"")) -> 0.96385542 | H21: =IF(ISBLANK(National_Annual!H20),"",IFERROR(IF(MAX(National_Annual!$F$20:$AD$20)=MIN(National_Annual!$F$20:$AD$20),0,(MAX(National_Annual!$F$20:$AD$20)-National_Annual!H20)/(MAX(National_Annual!$F$20:$AD$20)-MIN(National_Annual!$F$20:$AD$20))),"")) -> 0.92771084 | I21: =IF(ISBLANK(National_Annual!I20),"",IFERROR(IF(MAX(National_Annual!$F$20:$AD$20)=MIN(National_Annual!$F$20:$AD$20),0,(MAX(National_Annual!$F$20:$AD$20)-National_Annual!I20)/(MAX(National_Annual!$F$20:$AD$20)-MIN(National_Annual!$F$20:$AD$20))),"")) -> 0.90361446 | J21: =IF(ISBLANK(National_Annual!J20),"",IFERROR(IF(MAX(National_Annual!$F$20:$AD$20)=MIN(National_Annual!$F$20:$AD$20),0,(MAX(National_Annual!$F$20:$AD$20)-National_Annual!J20)/(MAX(National_Annual!$F$20:$AD$20)-MIN(National_Annual!$F$20:$AD$20))),"")) -> 0.84337349 | K21: =IF(ISBLANK(National_Annual!K20),"",IFERROR(IF(MAX(National_Annual!$F$20:$AD$20)=MIN(National_Annual!$F$20:$AD$20),0,(MAX(National_Annual!$F$20:$AD$20)-National_Annual!K20)/(MAX(National_Annual!$F$20:$AD$20)-MIN(National_Annual!$F$20:$AD$20))),"")) -> 0.80722892 | L21: =IF(ISBLANK(National_Annual!L20),"",IFERROR(IF(MAX(National_Annual!$F$20:$AD$20)=MIN(National_Annual!$F$20:$AD$20),0,(MAX(National_Annual!$F$20:$AD$20)-National_Annual!L20)/(MAX(National_Annual!$F$20:$AD$20)-MIN(National_Annual!$F$20:$AD$20))),"")) -> 0.75903614 | M21: =IF(ISBLANK(National_Annual!M20),"",IFERROR(IF(MAX(National_Annual!$F$20:$AD$20)=MIN(National_Annual!$F$20:$AD$20),0,(MAX(National_Annual!$F$20:$AD$20)-National_Annual!M20)/(MAX(National_Annual!$F$20:$AD$20)-MIN(National_Annual!$F$20:$AD$20))),"")) -> 0.72289157 | ... AD21: =IF(ISBLANK(National_Annual!AD20),"",IFERROR(IF(MAX(National_Annual!$F$20:$AD$20)=MIN(National_Annual!$F$20:$AD$20),0,(MAX(National_Annual!$F$20:$AD$20)-National_Annual!AD20)/(MAX(National_Annual!$F$20:$AD$20)-MIN(National_Annual!$F$20:$AD$20))),"")) -> 0
A22: NRI | B22: Network Readiness Index | C22: 0–100 | D22: C | E22: AC_TECH | F22: =IF(ISBLANK(National_Annual!F21),"",IFERROR(IF(MAX(National_Annual!$F$21:$AD$21)=MIN(National_Annual!$F$21:$AD$21),0,(MAX(National_Annual!$F$21:$AD$21)-National_Annual!F21)/(MAX(National_Annual!$F$21:$AD$21)-MIN(National_Annual!$F$21:$AD$21))),"")) | G22: =IF(ISBLANK(National_Annual!G21),"",IFERROR(IF(MAX(National_Annual!$F$21:$AD$21)=MIN(National_Annual!$F$21:$AD$21),0,(MAX(National_Annual!$F$21:$AD$21)-National_Annual!G21)/(MAX(National_Annual!$F$21:$AD$21)-MIN(National_Annual!$F$21:$AD$21))),"")) | H22: =IF(ISBLANK(National_Annual!H21),"",IFERROR(IF(MAX(National_Annual!$F$21:$AD$21)=MIN(National_Annual!$F$21:$AD$21),0,(MAX(National_Annual!$F$21:$AD$21)-National_Annual!H21)/(MAX(National_Annual!$F$21:$AD$21)-MIN(National_Annual!$F$21:$AD$21))),"")) | I22: =IF(ISBLANK(National_Annual!I21),"",IFERROR(IF(MAX(National_Annual!$F$21:$AD$21)=MIN(National_Annual!$F$21:$AD$21),0,(MAX(National_Annual!$F$21:$AD$21)-National_Annual!I21)/(MAX(National_Annual!$F$21:$AD$21)-MIN(National_Annual!$F$21:$AD$21))),"")) | J22: =IF(ISBLANK(National_Annual!J21),"",IFERROR(IF(MAX(National_Annual!$F$21:$AD$21)=MIN(National_Annual!$F$21:$AD$21),0,(MAX(National_Annual!$F$21:$AD$21)-National_Annual!J21)/(MAX(National_Annual!$F$21:$AD$21)-MIN(National_Annual!$F$21:$AD$21))),"")) | K22: =IF(ISBLANK(National_Annual!K21),"",IFERROR(IF(MAX(National_Annual!$F$21:$AD$21)=MIN(National_Annual!$F$21:$AD$21),0,(MAX(National_Annual!$F$21:$AD$21)-National_Annual!K21)/(MAX(National_Annual!$F$21:$AD$21)-MIN(National_Annual!$F$21:$AD$21))),"")) | L22: =IF(ISBLANK(National_Annual!L21),"",IFERROR(IF(MAX(National_Annual!$F$21:$AD$21)=MIN(National_Annual!$F$21:$AD$21),0,(MAX(National_Annual!$F$21:$AD$21)-National_Annual!L21)/(MAX(National_Annual!$F$21:$AD$21)-MIN(National_Annual!$F$21:$AD$21))),"")) | M22: =IF(ISBLANK(National_Annual!M21),"",IFERROR(IF(MAX(National_Annual!$F$21:$AD$21)=MIN(National_Annual!$F$21:$AD$21),0,(MAX(National_Annual!$F$21:$AD$21)-National_Annual!M21)/(MAX(National_Annual!$F$21:$AD$21)-MIN(National_Annual!$F$21:$AD$21))),"")) | ... AD22: =IF(ISBLANK(National_Annual!AD21),"",IFERROR(IF(MAX(National_Annual!$F$21:$AD$21)=MIN(National_Annual!$F$21:$AD$21),0,(MAX(National_Annual!$F$21:$AD$21)-National_Annual!AD21)/(MAX(National_Annual!$F$21:$AD$21)-MIN(National_Annual!$F$21:$AD$21))),"")) -> 0
A23: AI_READY | B23: Government AI Readiness Index | C23: 0–100 | D23: C | E23: AC_TECH | F23: =IF(ISBLANK(National_Annual!F22),"",IFERROR(IF(MAX(National_Annual!$F$22:$AD$22)=MIN(National_Annual!$F$22:$AD$22),0,(MAX(National_Annual!$F$22:$AD$22)-National_Annual!F22)/(MAX(National_Annual!$F$22:$AD$22)-MIN(National_Annual!$F$22:$AD$22))),"")) | G23: =IF(ISBLANK(National_Annual!G22),"",IFERROR(IF(MAX(National_Annual!$F$22:$AD$22)=MIN(National_Annual!$F$22:$AD$22),0,(MAX(National_Annual!$F$22:$AD$22)-National_Annual!G22)/(MAX(National_Annual!$F$22:$AD$22)-MIN(National_Annual!$F$22:$AD$22))),"")) | H23: =IF(ISBLANK(National_Annual!H22),"",IFERROR(IF(MAX(National_Annual!$F$22:$AD$22)=MIN(National_Annual!$F$22:$AD$22),0,(MAX(National_Annual!$F$22:$AD$22)-National_Annual!H22)/(MAX(National_Annual!$F$22:$AD$22)-MIN(National_Annual!$F$22:$AD$22))),"")) | I23: =IF(ISBLANK(National_Annual!I22),"",IFERROR(IF(MAX(National_Annual!$F$22:$AD$22)=MIN(National_Annual!$F$22:$AD$22),0,(MAX(National_Annual!$F$22:$AD$22)-National_Annual!I22)/(MAX(National_Annual!$F$22:$AD$22)-MIN(National_Annual!$F$22:$AD$22))),"")) | J23: =IF(ISBLANK(National_Annual!J22),"",IFERROR(IF(MAX(National_Annual!$F$22:$AD$22)=MIN(National_Annual!$F$22:$AD$22),0,(MAX(National_Annual!$F$22:$AD$22)-National_Annual!J22)/(MAX(National_Annual!$F$22:$AD$22)-MIN(National_Annual!$F$22:$AD$22))),"")) | K23: =IF(ISBLANK(National_Annual!K22),"",IFERROR(IF(MAX(National_Annual!$F$22:$AD$22)=MIN(National_Annual!$F$22:$AD$22),0,(MAX(National_Annual!$F$22:$AD$22)-National_Annual!K22)/(MAX(National_Annual!$F$22:$AD$22)-MIN(National_Annual!$F$22:$AD$22))),"")) | L23: =IF(ISBLANK(National_Annual!L22),"",IFERROR(IF(MAX(National_Annual!$F$22:$AD$22)=MIN(National_Annual!$F$22:$AD$22),0,(MAX(National_Annual!$F$22:$AD$22)-National_Annual!L22)/(MAX(National_Annual!$F$22:$AD$22)-MIN(National_Annual!$F$22:$AD$22))),"")) | M23: =IF(ISBLANK(National_Annual!M22),"",IFERROR(IF(MAX(National_Annual!$F$22:$AD$22)=MIN(National_Annual!$F$22:$AD$22),0,(MAX(National_Annual!$F$22:$AD$22)-National_Annual!M22)/(MAX(National_Annual!$F$22:$AD$22)-MIN(National_Annual!$F$22:$AD$22))),"")) | ... AD23: =IF(ISBLANK(National_Annual!AD22),"",IFERROR(IF(MAX(National_Annual!$F$22:$AD$22)=MIN(National_Annual!$F$22:$AD$22),0,(MAX(National_Annual!$F$22:$AD$22)-National_Annual!AD22)/(MAX(National_Annual!$F$22:$AD$22)-MIN(National_Annual!$F$22:$AD$22))),"")) -> 0
A24: NDGAIN_V | B24: ND-GAIN Vulnerability score | C24: 0–1 | D24: V | E24: REF | F24: =IF(ISBLANK(National_Annual!F23),"",IFERROR(IF(MAX(National_Annual!$F$23:$AD$23)=MIN(National_Annual!$F$23:$AD$23),0,(National_Annual!F23-MIN(National_Annual!$F$23:$AD$23))/(MAX(National_Annual!$F$23:$AD$23)-MIN(National_Annual!$F$23:$AD$23))),"")) -> 1 | G24: =IF(ISBLANK(National_Annual!G23),"",IFERROR(IF(MAX(National_Annual!$F$23:$AD$23)=MIN(National_Annual!$F$23:$AD$23),0,(National_Annual!G23-MIN(National_Annual!$F$23:$AD$23))/(MAX(National_Annual!$F$23:$AD$23)-MIN(National_Annual!$F$23:$AD$23))),"")) -> 0.92857143 | H24: =IF(ISBLANK(National_Annual!H23),"",IFERROR(IF(MAX(National_Annual!$F$23:$AD$23)=MIN(National_Annual!$F$23:$AD$23),0,(National_Annual!H23-MIN(National_Annual!$F$23:$AD$23))/(MAX(National_Annual!$F$23:$AD$23)-MIN(National_Annual!$F$23:$AD$23))),"")) -> 0.88095238 | I24: =IF(ISBLANK(National_Annual!I23),"",IFERROR(IF(MAX(National_Annual!$F$23:$AD$23)=MIN(National_Annual!$F$23:$AD$23),0,(National_Annual!I23-MIN(National_Annual!$F$23:$AD$23))/(MAX(National_Annual!$F$23:$AD$23)-MIN(National_Annual!$F$23:$AD$23))),"")) -> 0.83333333 | J24: =IF(ISBLANK(National_Annual!J23),"",IFERROR(IF(MAX(National_Annual!$F$23:$AD$23)=MIN(National_Annual!$F$23:$AD$23),0,(National_Annual!J23-MIN(National_Annual!$F$23:$AD$23))/(MAX(National_Annual!$F$23:$AD$23)-MIN(National_Annual!$F$23:$AD$23))),"")) -> 0.78571429 | K24: =IF(ISBLANK(National_Annual!K23),"",IFERROR(IF(MAX(National_Annual!$F$23:$AD$23)=MIN(National_Annual!$F$23:$AD$23),0,(National_Annual!K23-MIN(National_Annual!$F$23:$AD$23))/(MAX(National_Annual!$F$23:$AD$23)-MIN(National_Annual!$F$23:$AD$23))),"")) -> 0.73809524 | L24: =IF(ISBLANK(National_Annual!L23),"",IFERROR(IF(MAX(National_Annual!$F$23:$AD$23)=MIN(National_Annual!$F$23:$AD$23),0,(National_Annual!L23-MIN(National_Annual!$F$23:$AD$23))/(MAX(National_Annual!$F$23:$AD$23)-MIN(National_Annual!$F$23:$AD$23))),"")) -> 0.69047619 | M24: =IF(ISBLANK(National_Annual!M23),"",IFERROR(IF(MAX(National_Annual!$F$23:$AD$23)=MIN(National_Annual!$F$23:$AD$23),0,(National_Annual!M23-MIN(National_Annual!$F$23:$AD$23))/(MAX(National_Annual!$F$23:$AD$23)-MIN(National_Annual!$F$23:$AD$23))),"")) -> 0.64285714 | ... AD24: =IF(ISBLANK(National_Annual!AD23),"",IFERROR(IF(MAX(National_Annual!$F$23:$AD$23)=MIN(National_Annual!$F$23:$AD$23),0,(National_Annual!AD23-MIN(National_Annual!$F$23:$AD$23))/(MAX(National_Annual!$F$23:$AD$23)-MIN(National_Annual!$F$23:$AD$23))),"")) -> 0
